[2024-06-02T12:32:01.878+0000] {taskinstance.py:1956} INFO - Dependencies all met for dep_context=non-requeueable deps ti=<TaskInstance: Collect_Prices.Get_API_token scheduled__2024-06-02T12:30:00+00:00 [queued]>
[2024-06-02T12:32:01.887+0000] {taskinstance.py:1956} INFO - Dependencies all met for dep_context=requeueable deps ti=<TaskInstance: Collect_Prices.Get_API_token scheduled__2024-06-02T12:30:00+00:00 [queued]>
[2024-06-02T12:32:01.888+0000] {taskinstance.py:2170} INFO - Starting attempt 1 of 3
[2024-06-02T12:32:01.906+0000] {taskinstance.py:2191} INFO - Executing <Task(PythonOperator): Get_API_token> on 2024-06-02 12:30:00+00:00
[2024-06-02T12:32:01.917+0000] {standard_task_runner.py:60} INFO - Started process 4135 to run task
[2024-06-02T12:32:01.921+0000] {standard_task_runner.py:87} INFO - Running: ['***', 'tasks', 'run', 'Collect_Prices', 'Get_API_token', 'scheduled__2024-06-02T12:30:00+00:00', '--job-id', '21', '--raw', '--subdir', 'DAGS_FOLDER/BTC_prediction.py', '--cfg-path', '/tmp/tmpshw5tbb3']
[2024-06-02T12:32:01.923+0000] {standard_task_runner.py:88} INFO - Job 21: Subtask Get_API_token
[2024-06-02T12:32:01.944+0000] {warnings.py:109} WARNING - /home/***/.local/lib/python3.8/site-packages/***/settings.py:194: DeprecationWarning: The sql_alchemy_conn option in [core] has been moved to the sql_alchemy_conn option in [database] - the old setting has been used, but please update your config.
  SQL_ALCHEMY_CONN = conf.get("database", "SQL_ALCHEMY_CONN")

[2024-06-02T12:32:01.987+0000] {task_command.py:423} INFO - Running <TaskInstance: Collect_Prices.Get_API_token scheduled__2024-06-02T12:30:00+00:00 [running]> on host e40c13df5558
[2024-06-02T12:32:02.089+0000] {taskinstance.py:2480} INFO - Exporting env vars: AIRFLOW_CTX_DAG_OWNER='***' AIRFLOW_CTX_DAG_ID='Collect_Prices' AIRFLOW_CTX_TASK_ID='Get_API_token' AIRFLOW_CTX_EXECUTION_DATE='2024-06-02T12:30:00+00:00' AIRFLOW_CTX_TRY_NUMBER='1' AIRFLOW_CTX_DAG_RUN_ID='scheduled__2024-06-02T12:30:00+00:00'
[2024-06-02T12:32:04.148+0000] {taskinstance.py:2698} ERROR - Task failed with exception
Traceback (most recent call last):
  File "/home/airflow/.local/lib/python3.8/site-packages/urllib3/connection.py", line 174, in _new_conn
    conn = connection.create_connection(
  File "/home/airflow/.local/lib/python3.8/site-packages/urllib3/util/connection.py", line 95, in create_connection
    raise err
  File "/home/airflow/.local/lib/python3.8/site-packages/urllib3/util/connection.py", line 85, in create_connection
    sock.connect(sa)
ConnectionRefusedError: [Errno 111] Connection refused

During handling of the above exception, another exception occurred:

Traceback (most recent call last):
  File "/home/airflow/.local/lib/python3.8/site-packages/urllib3/connectionpool.py", line 715, in urlopen
    httplib_response = self._make_request(
  File "/home/airflow/.local/lib/python3.8/site-packages/urllib3/connectionpool.py", line 416, in _make_request
    conn.request(method, url, **httplib_request_kw)
  File "/home/airflow/.local/lib/python3.8/site-packages/urllib3/connection.py", line 244, in request
    super(HTTPConnection, self).request(method, url, body=body, headers=headers)
  File "/usr/local/lib/python3.8/http/client.py", line 1256, in request
    self._send_request(method, url, body, headers, encode_chunked)
  File "/usr/local/lib/python3.8/http/client.py", line 1302, in _send_request
    self.endheaders(body, encode_chunked=encode_chunked)
  File "/usr/local/lib/python3.8/http/client.py", line 1251, in endheaders
    self._send_output(message_body, encode_chunked=encode_chunked)
  File "/usr/local/lib/python3.8/http/client.py", line 1011, in _send_output
    self.send(msg)
  File "/usr/local/lib/python3.8/http/client.py", line 951, in send
    self.connect()
  File "/home/airflow/.local/lib/python3.8/site-packages/urllib3/connection.py", line 205, in connect
    conn = self._new_conn()
  File "/home/airflow/.local/lib/python3.8/site-packages/urllib3/connection.py", line 186, in _new_conn
    raise NewConnectionError(
urllib3.exceptions.NewConnectionError: <urllib3.connection.HTTPConnection object at 0x7f8b895c6af0>: Failed to establish a new connection: [Errno 111] Connection refused

During handling of the above exception, another exception occurred:

Traceback (most recent call last):
  File "/home/airflow/.local/lib/python3.8/site-packages/requests/adapters.py", line 486, in send
    resp = conn.urlopen(
  File "/home/airflow/.local/lib/python3.8/site-packages/urllib3/connectionpool.py", line 799, in urlopen
    retries = retries.increment(
  File "/home/airflow/.local/lib/python3.8/site-packages/urllib3/util/retry.py", line 592, in increment
    raise MaxRetryError(_pool, url, error or ResponseError(cause))
urllib3.exceptions.MaxRetryError: HTTPConnectionPool(host='192.168.0.6', port=8000): Max retries exceeded with url: /Get_token (Caused by NewConnectionError('<urllib3.connection.HTTPConnection object at 0x7f8b895c6af0>: Failed to establish a new connection: [Errno 111] Connection refused'))

During handling of the above exception, another exception occurred:

Traceback (most recent call last):
  File "/home/airflow/.local/lib/python3.8/site-packages/airflow/models/taskinstance.py", line 433, in _execute_task
    result = execute_callable(context=context, **execute_callable_kwargs)
  File "/home/airflow/.local/lib/python3.8/site-packages/airflow/operators/python.py", line 199, in execute
    return_value = self.execute_callable()
  File "/home/airflow/.local/lib/python3.8/site-packages/airflow/operators/python.py", line 216, in execute_callable
    return self.python_callable(*self.op_args, **self.op_kwargs)
  File "/opt/airflow/dags/BTC_prediction.py", line 26, in get_access_token
    response = requests.post(url, data=data)
  File "/home/airflow/.local/lib/python3.8/site-packages/requests/api.py", line 115, in post
    return request("post", url, data=data, json=json, **kwargs)
  File "/home/airflow/.local/lib/python3.8/site-packages/requests/api.py", line 59, in request
    return session.request(method=method, url=url, **kwargs)
  File "/home/airflow/.local/lib/python3.8/site-packages/requests/sessions.py", line 589, in request
    resp = self.send(prep, **send_kwargs)
  File "/home/airflow/.local/lib/python3.8/site-packages/requests/sessions.py", line 703, in send
    r = adapter.send(request, **kwargs)
  File "/home/airflow/.local/lib/python3.8/site-packages/requests/adapters.py", line 519, in send
    raise ConnectionError(e, request=request)
requests.exceptions.ConnectionError: HTTPConnectionPool(host='192.168.0.6', port=8000): Max retries exceeded with url: /Get_token (Caused by NewConnectionError('<urllib3.connection.HTTPConnection object at 0x7f8b895c6af0>: Failed to establish a new connection: [Errno 111] Connection refused'))
[2024-06-02T12:32:04.161+0000] {taskinstance.py:1138} INFO - Marking task as UP_FOR_RETRY. dag_id=Collect_Prices, task_id=Get_API_token, execution_date=20240602T123000, start_date=20240602T123201, end_date=20240602T123204
[2024-06-02T12:32:04.178+0000] {standard_task_runner.py:107} ERROR - Failed to execute job 21 for task Get_API_token (HTTPConnectionPool(host='192.168.0.6', port=8000): Max retries exceeded with url: /Get_token (Caused by NewConnectionError('<urllib3.connection.HTTPConnection object at 0x7f8b895c6af0>: Failed to establish a new connection: [Errno 111] Connection refused')); 4135)
[2024-06-02T12:32:04.226+0000] {local_task_job_runner.py:234} INFO - Task exited with return code 1
[2024-06-02T12:32:04.254+0000] {taskinstance.py:3280} INFO - 0 downstream tasks scheduled from follow-on schedule check
